<?xml version="1.0" encoding="UTF-8"?>
<robot name="m2wr" xmlns:xacro="http://www.ros.org/wiki/xacro">
  <xacro:include filename="$(find myrob)/urdf/m2wr.gazebo" />
  <xacro:include
    filename="$(find myrob)/urdf/materials.xacro" />
  <xacro:include
    filename="$(find myrob)/urdf/macro.xacro" />


  <xacro:link_wheel name="link_right_wheel" />
  <xacro:joint_wheel
    name="joint_right_wheel" child="link_right_wheel" origin_xyz="0.15 -0.165 0" />

  <xacro:link_wheel
    name="link_left_wheel" />
  <xacro:joint_wheel name="joint_left_wheel" child="link_left_wheel"
    origin_xyz="0.15 0.165 0" />


  <!-- chassis_link -->

  <link name="link_chassis">

    <pose>0 0 0.1 0 0 0</pose>

    <inertial>
      <mass value="5" />
      <origin rpy="0 0 0" xyz="0 0 0" />
      <inertia ixx="0.0395416666667" ixy="0" ixz="0" iyy="0.106208333333" iyz="0"
        izz="0.106208333333" />
    </inertial>

    <collision name="collision_chassis">
      <geometry>
        <box size="0.47 0.33 0.02" />
      </geometry>
    </collision>

    <visual>
      <origin rpy="0 0 0" xyz="0 0 0" />
      <geometry>
        <box size="0.47 0.33 0.02" />
      </geometry>
      <material name="blue" />
    </visual>


    <collision name="cyl1_collision">
      <origin rpy="0 0 0" xyz="-0.215 -0.14 0.045" />
      <geometry>
        <cylinder length="0.07" radius="0.01" />
      </geometry>
    </collision>

    <visual name="cyl1_visual">
      <origin rpy="0 0 0" xyz="-0.215 -0.14 0.045" />
      <geometry>
        <cylinder length="0.07" radius="0.01" />
      </geometry>
    </visual>


    <collision name="cyl2_collision">
      <origin rpy="0 0 0" xyz="-0.215 0.14 0.045" />
      <geometry>
        <cylinder length="0.07" radius="0.01" />
      </geometry>
    </collision>

    <visual name="cyl2_visual">
      <origin rpy="0 0 0" xyz="-0.215 0.14 0.045" />
      <geometry>
        <cylinder length="0.07" radius="0.01" />
      </geometry>
    </visual>

    <collision name="cyl3_collision">
      <origin rpy="0 0 0" xyz="0.215 -0.14 0.045" />
      <geometry>
        <cylinder length="0.07" radius="0.01" />
      </geometry>
    </collision>

    <visual name="cyl3_visual">
      <origin rpy="0 0 0" xyz="0.215 -0.14 0.045" />
      <geometry>
        <cylinder length="0.07" radius="0.01" />
      </geometry>
    </visual>


    <collision name="cyl4_collision">
      <origin rpy="0 0 0" xyz="0.215 0.14 0.045" />
      <geometry>
        <cylinder length="0.07" radius="0.01" />
      </geometry>
    </collision>

    <visual name="cyl4_visual">
      <origin rpy="0 0 0" xyz="0.215 0.14 0.045" />
      <geometry>
        <cylinder length="0.07" radius="0.01" />
      </geometry>
    </visual>


    <collision name="collision_top_chassis">
      <geometry>
        <box size="0.47 0.33 0.02" />
      </geometry>
    </collision>

    <visual>
      <origin rpy="0 0 0" xyz="0 0 0.08" />
      <geometry>
        <box size="0.47 0.33 0.02" />
      </geometry>
      <material name="blue" />
    </visual>


  </link>

  <!-- caster_link -->
  <link
    name="caster_rear">
    <inertial>
      <mass value="0.2" />
      <origin rpy="0 1.5707 1.5707" xyz="0 0 0" />
      <inertia ixx="0.00052666666" ixy="0" ixz="0" iyy="0.00052666666" iyz="0" izz="0.001" />
    </inertial>
    <collision>
      <origin rpy="0 1.5707 1.5707" xyz="0 0 0" />
      <geometry>
        <cylinder length="0.03" radius="0.02" />
      </geometry>
      <surface>
        <friction>
          <ode>
            <mu>0</mu>
            <mu2>0</mu2>
            <slip1>1.0</slip1>
            <slip2>1.0</slip2>
          </ode>
        </friction>
      </surface>
    </collision>
    <visual>
      <origin rpy="0 1.5707 1.5707" xyz="0 0 0" />
      <geometry>
        <cylinder length="0.03" radius="0.02" />
      </geometry>
    </visual>
  </link>


  <!-- caster_joint -->
  <!-- <joint
    name="caster_rear_joint" type="fixed">
    <origin rpy="0 0 0" xyz="-0.15 0 -0.03" />
    <child link="caster_rear" />
    <parent link="link_chassis" />
    <axis
      rpy="0 0 0" xyz="0 0 1" />
       the kinematic constraintes of the caster wheel "as defined in the article" are pi/2 and -pi/2
    <limit effort="1000" velocity="1000"/>  
    <joint_properties
      damping="1.0" friction="1.0" />
  </joint> -->




  <joint
    name="caster_rear_joint" type="revolute">
    <origin rpy="0 0 0" xyz="-0.15 0 -0.03" />
    <child link="caster_rear" />
    <parent link="link_chassis" />
    <axis
      rpy="0 0 0" xyz="0 0 1" />
       <!-- the kinematic constraintes of the caster wheel "as defined in the article" are pi/2 and -pi/2 -->
    <limit effort="1000" velocity="1000" upper="1.57" lower="-1.57" />  
    <joint_properties
      damping="1.0" friction="1.0" />
  </joint>
  <transmission name="caster_rear_trans">
    <type>transmission_interface/SimpleTransmission</type>
    <joint name="caster_rear_joint">
      <hardwareInterface>PositionJointInterface</hardwareInterface>
    </joint>
    <actuator name="caster_rear_servo">
      <mechanicalReduction>1</mechanicalReduction>
      <hardwareInterface>PositionJointInterface</hardwareInterface>
    </actuator>
  </transmission>

  <xacro:property name="camera_link" value="0.05" />
  <link
    name="camera_link">
    <collision>
      <origin xyz="0 0 0" rpy="0 0 0" />
      <geometry>
        <box size="${camera_link} ${camera_link} ${camera_link}" />
      </geometry>
    </collision>

    <visual>
      <origin xyz="0 0 0" rpy="0 0 0" />
      <geometry>
        <box size="${camera_link} ${camera_link} ${camera_link}" />
      </geometry>
      <material name="red" />
    </visual>

    <inertial>
      <mass value="1e-5" />
      <origin xyz="0 0 0" rpy="0 0 0" />
      <inertia ixx="1e-6" ixy="0" ixz="0" iyy="1e-6" iyz="0" izz="1e-6" />
    </inertial>
  </link>
  <joint
    name="camera_joint" type="fixed">
    <axis xyz="0 1 0" />
    <origin xyz="0.225 0 0.124" rpy="0 0.72 0" />
    <parent link="link_chassis" />
    <child link="camera_link" />
  </joint>
</robot>